<?xml version="1.0" encoding="UTF-8"?><testrun name="215HWA2" project="215HWA2" tests="17" started="17" failures="10" errors="0" ignored="0">
  <testsuite name="DoubleVectorTester" time="0.003">
    <testcase name="testLotsOfDenseSets" classname="DoubleVectorTester" time="0.0"/>
    <testcase name="testL1NormSparseShort" classname="DoubleVectorTester" time="0.0">
      <failure>junit.framework.AssertionFailedError: Got an out of bounds exception on set/get pos 8 not expecting one!

	at junit.framework.Assert.fail(Assert.java:57)
	at junit.framework.TestCase.fail(TestCase.java:227)
	at DoubleVectorTester.l1NormTester(DoubleVectorTester.java:58)
	at DoubleVectorTester.testL1NormSparseShort(DoubleVectorTester.java:277)
	at sun.reflect.NativeMethodAccessorImpl.invoke0(Native Method)
	at sun.reflect.NativeMethodAccessorImpl.invoke(NativeMethodAccessorImpl.java:62)
	at sun.reflect.DelegatingMethodAccessorImpl.invoke(DelegatingMethodAccessorImpl.java:43)
	at java.lang.reflect.Method.invoke(Method.java:483)
	at junit.framework.TestCase.runTest(TestCase.java:176)
	at junit.framework.TestCase.runBare(TestCase.java:141)
	at junit.framework.TestResult$1.protect(TestResult.java:122)
	at junit.framework.TestResult.runProtected(TestResult.java:142)
	at junit.framework.TestResult.run(TestResult.java:125)
	at junit.framework.TestCase.run(TestCase.java:129)
	at junit.framework.TestSuite.runTest(TestSuite.java:255)
	at junit.framework.TestSuite.run(TestSuite.java:250)
	at org.junit.internal.runners.JUnit38ClassRunner.run(JUnit38ClassRunner.java:84)
	at org.eclipse.jdt.internal.junit4.runner.JUnit4TestReference.run(JUnit4TestReference.java:50)
	at org.eclipse.jdt.internal.junit.runner.TestExecution.run(TestExecution.java:38)
	at org.eclipse.jdt.internal.junit.runner.RemoteTestRunner.runTests(RemoteTestRunner.java:459)
	at org.eclipse.jdt.internal.junit.runner.RemoteTestRunner.runTests(RemoteTestRunner.java:675)
	at org.eclipse.jdt.internal.junit.runner.RemoteTestRunner.run(RemoteTestRunner.java:382)
	at org.eclipse.jdt.internal.junit.runner.RemoteTestRunner.main(RemoteTestRunner.java:192)

</failure>
    </testcase>
    <testcase name="testLotsOfAdds" classname="DoubleVectorTester" time="0.0">
      <failure>junit.framework.AssertionFailedError: Got an out of bounds exception on set/get pos 36 not expecting one!

	at junit.framework.Assert.fail(Assert.java:57)
	at junit.framework.TestCase.fail(TestCase.java:227)
	at DoubleVectorTester.testLotsOfAdds(DoubleVectorTester.java:405)
	at sun.reflect.NativeMethodAccessorImpl.invoke0(Native Method)
	at sun.reflect.NativeMethodAccessorImpl.invoke(NativeMethodAccessorImpl.java:62)
	at sun.reflect.DelegatingMethodAccessorImpl.invoke(DelegatingMethodAccessorImpl.java:43)
	at java.lang.reflect.Method.invoke(Method.java:483)
	at junit.framework.TestCase.runTest(TestCase.java:176)
	at junit.framework.TestCase.runBare(TestCase.java:141)
	at junit.framework.TestResult$1.protect(TestResult.java:122)
	at junit.framework.TestResult.runProtected(TestResult.java:142)
	at junit.framework.TestResult.run(TestResult.java:125)
	at junit.framework.TestCase.run(TestCase.java:129)
	at junit.framework.TestSuite.runTest(TestSuite.java:255)
	at junit.framework.TestSuite.run(TestSuite.java:250)
	at org.junit.internal.runners.JUnit38ClassRunner.run(JUnit38ClassRunner.java:84)
	at org.eclipse.jdt.internal.junit4.runner.JUnit4TestReference.run(JUnit4TestReference.java:50)
	at org.eclipse.jdt.internal.junit.runner.TestExecution.run(TestExecution.java:38)
	at org.eclipse.jdt.internal.junit.runner.RemoteTestRunner.runTests(RemoteTestRunner.java:459)
	at org.eclipse.jdt.internal.junit.runner.RemoteTestRunner.runTests(RemoteTestRunner.java:675)
	at org.eclipse.jdt.internal.junit.runner.RemoteTestRunner.run(RemoteTestRunner.java:382)
	at org.eclipse.jdt.internal.junit.runner.RemoteTestRunner.main(RemoteTestRunner.java:192)

</failure>
    </testcase>
    <testcase name="testNormalizeDense" classname="DoubleVectorTester" time="0.0"/>
    <testcase name="testL1NormDenseShort" classname="DoubleVectorTester" time="0.0"/>
    <testcase name="testOutOfBounds" classname="DoubleVectorTester" time="0.0"/>
    <testcase name="testLotsOfSparseSets" classname="DoubleVectorTester" time="0.0">
      <failure>junit.framework.AssertionFailedError: Got an out of bounds exception on set/get pos 0 not expecting one!

	at junit.framework.Assert.fail(Assert.java:57)
	at junit.framework.TestCase.fail(TestCase.java:227)
	at DoubleVectorTester.doLotsOfSets(DoubleVectorTester.java:83)
	at DoubleVectorTester.testLotsOfSparseSets(DoubleVectorTester.java:223)
	at sun.reflect.NativeMethodAccessorImpl.invoke0(Native Method)
	at sun.reflect.NativeMethodAccessorImpl.invoke(NativeMethodAccessorImpl.java:62)
	at sun.reflect.DelegatingMethodAccessorImpl.invoke(DelegatingMethodAccessorImpl.java:43)
	at java.lang.reflect.Method.invoke(Method.java:483)
	at junit.framework.TestCase.runTest(TestCase.java:176)
	at junit.framework.TestCase.runBare(TestCase.java:141)
	at junit.framework.TestResult$1.protect(TestResult.java:122)
	at junit.framework.TestResult.runProtected(TestResult.java:142)
	at junit.framework.TestResult.run(TestResult.java:125)
	at junit.framework.TestCase.run(TestCase.java:129)
	at junit.framework.TestSuite.runTest(TestSuite.java:255)
	at junit.framework.TestSuite.run(TestSuite.java:250)
	at org.junit.internal.runners.JUnit38ClassRunner.run(JUnit38ClassRunner.java:84)
	at org.eclipse.jdt.internal.junit4.runner.JUnit4TestReference.run(JUnit4TestReference.java:50)
	at org.eclipse.jdt.internal.junit.runner.TestExecution.run(TestExecution.java:38)
	at org.eclipse.jdt.internal.junit.runner.RemoteTestRunner.runTests(RemoteTestRunner.java:459)
	at org.eclipse.jdt.internal.junit.runner.RemoteTestRunner.runTests(RemoteTestRunner.java:675)
	at org.eclipse.jdt.internal.junit.runner.RemoteTestRunner.run(RemoteTestRunner.java:382)
	at org.eclipse.jdt.internal.junit.runner.RemoteTestRunner.main(RemoteTestRunner.java:192)

</failure>
    </testcase>
    <testcase name="testLotsOfSparseSetsWithAddToAll" classname="DoubleVectorTester" time="0.0">
      <failure>junit.framework.AssertionFailedError: Got an out of bounds exception on set/get pos 0 not expecting one!

	at junit.framework.Assert.fail(Assert.java:57)
	at junit.framework.TestCase.fail(TestCase.java:227)
	at DoubleVectorTester.doLotsOfSets(DoubleVectorTester.java:83)
	at DoubleVectorTester.testLotsOfSparseSetsWithAddToAll(DoubleVectorTester.java:253)
	at sun.reflect.NativeMethodAccessorImpl.invoke0(Native Method)
	at sun.reflect.NativeMethodAccessorImpl.invoke(NativeMethodAccessorImpl.java:62)
	at sun.reflect.DelegatingMethodAccessorImpl.invoke(DelegatingMethodAccessorImpl.java:43)
	at java.lang.reflect.Method.invoke(Method.java:483)
	at junit.framework.TestCase.runTest(TestCase.java:176)
	at junit.framework.TestCase.runBare(TestCase.java:141)
	at junit.framework.TestResult$1.protect(TestResult.java:122)
	at junit.framework.TestResult.runProtected(TestResult.java:142)
	at junit.framework.TestResult.run(TestResult.java:125)
	at junit.framework.TestCase.run(TestCase.java:129)
	at junit.framework.TestSuite.runTest(TestSuite.java:255)
	at junit.framework.TestSuite.run(TestSuite.java:250)
	at org.junit.internal.runners.JUnit38ClassRunner.run(JUnit38ClassRunner.java:84)
	at org.eclipse.jdt.internal.junit4.runner.JUnit4TestReference.run(JUnit4TestReference.java:50)
	at org.eclipse.jdt.internal.junit.runner.TestExecution.run(TestExecution.java:38)
	at org.eclipse.jdt.internal.junit.runner.RemoteTestRunner.runTests(RemoteTestRunner.java:459)
	at org.eclipse.jdt.internal.junit.runner.RemoteTestRunner.runTests(RemoteTestRunner.java:675)
	at org.eclipse.jdt.internal.junit.runner.RemoteTestRunner.run(RemoteTestRunner.java:382)
	at org.eclipse.jdt.internal.junit.runner.RemoteTestRunner.main(RemoteTestRunner.java:192)

</failure>
    </testcase>
    <testcase name="testL1NormSparseLong" classname="DoubleVectorTester" time="0.001">
      <failure>junit.framework.AssertionFailedError: Got an out of bounds exception on set/get pos 8 not expecting one!

	at junit.framework.Assert.fail(Assert.java:57)
	at junit.framework.TestCase.fail(TestCase.java:227)
	at DoubleVectorTester.l1NormTester(DoubleVectorTester.java:58)
	at DoubleVectorTester.testL1NormSparseLong(DoubleVectorTester.java:285)
	at sun.reflect.NativeMethodAccessorImpl.invoke0(Native Method)
	at sun.reflect.NativeMethodAccessorImpl.invoke(NativeMethodAccessorImpl.java:62)
	at sun.reflect.DelegatingMethodAccessorImpl.invoke(DelegatingMethodAccessorImpl.java:43)
	at java.lang.reflect.Method.invoke(Method.java:483)
	at junit.framework.TestCase.runTest(TestCase.java:176)
	at junit.framework.TestCase.runBare(TestCase.java:141)
	at junit.framework.TestResult$1.protect(TestResult.java:122)
	at junit.framework.TestResult.runProtected(TestResult.java:142)
	at junit.framework.TestResult.run(TestResult.java:125)
	at junit.framework.TestCase.run(TestCase.java:129)
	at junit.framework.TestSuite.runTest(TestSuite.java:255)
	at junit.framework.TestSuite.run(TestSuite.java:250)
	at org.junit.internal.runners.JUnit38ClassRunner.run(JUnit38ClassRunner.java:84)
	at org.eclipse.jdt.internal.junit4.runner.JUnit4TestReference.run(JUnit4TestReference.java:50)
	at org.eclipse.jdt.internal.junit.runner.TestExecution.run(TestExecution.java:38)
	at org.eclipse.jdt.internal.junit.runner.RemoteTestRunner.runTests(RemoteTestRunner.java:459)
	at org.eclipse.jdt.internal.junit.runner.RemoteTestRunner.runTests(RemoteTestRunner.java:675)
	at org.eclipse.jdt.internal.junit.runner.RemoteTestRunner.run(RemoteTestRunner.java:382)
	at org.eclipse.jdt.internal.junit.runner.RemoteTestRunner.main(RemoteTestRunner.java:192)

</failure>
    </testcase>
    <testcase name="testSingleSparseSetSize1" classname="DoubleVectorTester" time="0.0">
      <failure>junit.framework.AssertionFailedError: Got an out of bounds exception on set/get... not expecting one!

	at junit.framework.Assert.fail(Assert.java:57)
	at junit.framework.TestCase.fail(TestCase.java:227)
	at DoubleVectorTester.trivialGetAndSet(DoubleVectorTester.java:125)
	at DoubleVectorTester.testSingleSparseSetSize1(DoubleVectorTester.java:179)
	at sun.reflect.NativeMethodAccessorImpl.invoke0(Native Method)
	at sun.reflect.NativeMethodAccessorImpl.invoke(NativeMethodAccessorImpl.java:62)
	at sun.reflect.DelegatingMethodAccessorImpl.invoke(DelegatingMethodAccessorImpl.java:43)
	at java.lang.reflect.Method.invoke(Method.java:483)
	at junit.framework.TestCase.runTest(TestCase.java:176)
	at junit.framework.TestCase.runBare(TestCase.java:141)
	at junit.framework.TestResult$1.protect(TestResult.java:122)
	at junit.framework.TestResult.runProtected(TestResult.java:142)
	at junit.framework.TestResult.run(TestResult.java:125)
	at junit.framework.TestCase.run(TestCase.java:129)
	at junit.framework.TestSuite.runTest(TestSuite.java:255)
	at junit.framework.TestSuite.run(TestSuite.java:250)
	at org.junit.internal.runners.JUnit38ClassRunner.run(JUnit38ClassRunner.java:84)
	at org.eclipse.jdt.internal.junit4.runner.JUnit4TestReference.run(JUnit4TestReference.java:50)
	at org.eclipse.jdt.internal.junit.runner.TestExecution.run(TestExecution.java:38)
	at org.eclipse.jdt.internal.junit.runner.RemoteTestRunner.runTests(RemoteTestRunner.java:459)
	at org.eclipse.jdt.internal.junit.runner.RemoteTestRunner.runTests(RemoteTestRunner.java:675)
	at org.eclipse.jdt.internal.junit.runner.RemoteTestRunner.run(RemoteTestRunner.java:382)
	at org.eclipse.jdt.internal.junit.runner.RemoteTestRunner.main(RemoteTestRunner.java:192)

</failure>
    </testcase>
    <testcase name="testSingleDenseSetSize1" classname="DoubleVectorTester" time="0.0">
      <failure>junit.framework.AssertionFailedError: Got an out of bounds exception on set/get... not expecting one!

	at junit.framework.Assert.fail(Assert.java:57)
	at junit.framework.TestCase.fail(TestCase.java:227)
	at DoubleVectorTester.trivialGetAndSet(DoubleVectorTester.java:125)
	at DoubleVectorTester.testSingleDenseSetSize1(DoubleVectorTester.java:171)
	at sun.reflect.NativeMethodAccessorImpl.invoke0(Native Method)
	at sun.reflect.NativeMethodAccessorImpl.invoke(NativeMethodAccessorImpl.java:62)
	at sun.reflect.DelegatingMethodAccessorImpl.invoke(DelegatingMethodAccessorImpl.java:43)
	at java.lang.reflect.Method.invoke(Method.java:483)
	at junit.framework.TestCase.runTest(TestCase.java:176)
	at junit.framework.TestCase.runBare(TestCase.java:141)
	at junit.framework.TestResult$1.protect(TestResult.java:122)
	at junit.framework.TestResult.runProtected(TestResult.java:142)
	at junit.framework.TestResult.run(TestResult.java:125)
	at junit.framework.TestCase.run(TestCase.java:129)
	at junit.framework.TestSuite.runTest(TestSuite.java:255)
	at junit.framework.TestSuite.run(TestSuite.java:250)
	at org.junit.internal.runners.JUnit38ClassRunner.run(JUnit38ClassRunner.java:84)
	at org.eclipse.jdt.internal.junit4.runner.JUnit4TestReference.run(JUnit4TestReference.java:50)
	at org.eclipse.jdt.internal.junit.runner.TestExecution.run(TestExecution.java:38)
	at org.eclipse.jdt.internal.junit.runner.RemoteTestRunner.runTests(RemoteTestRunner.java:459)
	at org.eclipse.jdt.internal.junit.runner.RemoteTestRunner.runTests(RemoteTestRunner.java:675)
	at org.eclipse.jdt.internal.junit.runner.RemoteTestRunner.run(RemoteTestRunner.java:382)
	at org.eclipse.jdt.internal.junit.runner.RemoteTestRunner.main(RemoteTestRunner.java:192)

</failure>
    </testcase>
    <testcase name="testSingleSparseSetSize1000" classname="DoubleVectorTester" time="0.0">
      <failure>junit.framework.AssertionFailedError: Got an out of bounds exception on set/get... not expecting one!

	at junit.framework.Assert.fail(Assert.java:57)
	at junit.framework.TestCase.fail(TestCase.java:227)
	at DoubleVectorTester.trivialGetAndSet(DoubleVectorTester.java:125)
	at DoubleVectorTester.testSingleSparseSetSize1000(DoubleVectorTester.java:195)
	at sun.reflect.NativeMethodAccessorImpl.invoke0(Native Method)
	at sun.reflect.NativeMethodAccessorImpl.invoke(NativeMethodAccessorImpl.java:62)
	at sun.reflect.DelegatingMethodAccessorImpl.invoke(DelegatingMethodAccessorImpl.java:43)
	at java.lang.reflect.Method.invoke(Method.java:483)
	at junit.framework.TestCase.runTest(TestCase.java:176)
	at junit.framework.TestCase.runBare(TestCase.java:141)
	at junit.framework.TestResult$1.protect(TestResult.java:122)
	at junit.framework.TestResult.runProtected(TestResult.java:142)
	at junit.framework.TestResult.run(TestResult.java:125)
	at junit.framework.TestCase.run(TestCase.java:129)
	at junit.framework.TestSuite.runTest(TestSuite.java:255)
	at junit.framework.TestSuite.run(TestSuite.java:250)
	at org.junit.internal.runners.JUnit38ClassRunner.run(JUnit38ClassRunner.java:84)
	at org.eclipse.jdt.internal.junit4.runner.JUnit4TestReference.run(JUnit4TestReference.java:50)
	at org.eclipse.jdt.internal.junit.runner.TestExecution.run(TestExecution.java:38)
	at org.eclipse.jdt.internal.junit.runner.RemoteTestRunner.runTests(RemoteTestRunner.java:459)
	at org.eclipse.jdt.internal.junit.runner.RemoteTestRunner.runTests(RemoteTestRunner.java:675)
	at org.eclipse.jdt.internal.junit.runner.RemoteTestRunner.run(RemoteTestRunner.java:382)
	at org.eclipse.jdt.internal.junit.runner.RemoteTestRunner.main(RemoteTestRunner.java:192)

</failure>
    </testcase>
    <testcase name="testRounding" classname="DoubleVectorTester" time="0.0">
      <failure>junit.framework.AssertionFailedError: not expecting an out-of-bounds here
	at junit.framework.Assert.fail(Assert.java:57)
	at junit.framework.TestCase.fail(TestCase.java:227)
	at DoubleVectorTester.testRounding(DoubleVectorTester.java:307)
	at sun.reflect.NativeMethodAccessorImpl.invoke0(Native Method)
	at sun.reflect.NativeMethodAccessorImpl.invoke(NativeMethodAccessorImpl.java:62)
	at sun.reflect.DelegatingMethodAccessorImpl.invoke(DelegatingMethodAccessorImpl.java:43)
	at java.lang.reflect.Method.invoke(Method.java:483)
	at junit.framework.TestCase.runTest(TestCase.java:176)
	at junit.framework.TestCase.runBare(TestCase.java:141)
	at junit.framework.TestResult$1.protect(TestResult.java:122)
	at junit.framework.TestResult.runProtected(TestResult.java:142)
	at junit.framework.TestResult.run(TestResult.java:125)
	at junit.framework.TestCase.run(TestCase.java:129)
	at junit.framework.TestSuite.runTest(TestSuite.java:255)
	at junit.framework.TestSuite.run(TestSuite.java:250)
	at org.junit.internal.runners.JUnit38ClassRunner.run(JUnit38ClassRunner.java:84)
	at org.eclipse.jdt.internal.junit4.runner.JUnit4TestReference.run(JUnit4TestReference.java:50)
	at org.eclipse.jdt.internal.junit.runner.TestExecution.run(TestExecution.java:38)
	at org.eclipse.jdt.internal.junit.runner.RemoteTestRunner.runTests(RemoteTestRunner.java:459)
	at org.eclipse.jdt.internal.junit.runner.RemoteTestRunner.runTests(RemoteTestRunner.java:675)
	at org.eclipse.jdt.internal.junit.runner.RemoteTestRunner.run(RemoteTestRunner.java:382)
	at org.eclipse.jdt.internal.junit.runner.RemoteTestRunner.main(RemoteTestRunner.java:192)

</failure>
    </testcase>
    <testcase name="testNormalizeSparse" classname="DoubleVectorTester" time="0.0">
      <failure>junit.framework.AssertionFailedError: Got an out of bounds exception on set/get pos 8 not expecting one!

	at junit.framework.Assert.fail(Assert.java:57)
	at junit.framework.TestCase.fail(TestCase.java:227)
	at DoubleVectorTester.l1NormTester(DoubleVectorTester.java:58)
	at DoubleVectorTester.normalizeTester(DoubleVectorTester.java:137)
	at DoubleVectorTester.testNormalizeSparse(DoubleVectorTester.java:443)
	at sun.reflect.NativeMethodAccessorImpl.invoke0(Native Method)
	at sun.reflect.NativeMethodAccessorImpl.invoke(NativeMethodAccessorImpl.java:62)
	at sun.reflect.DelegatingMethodAccessorImpl.invoke(DelegatingMethodAccessorImpl.java:43)
	at java.lang.reflect.Method.invoke(Method.java:483)
	at junit.framework.TestCase.runTest(TestCase.java:176)
	at junit.framework.TestCase.runBare(TestCase.java:141)
	at junit.framework.TestResult$1.protect(TestResult.java:122)
	at junit.framework.TestResult.runProtected(TestResult.java:142)
	at junit.framework.TestResult.run(TestResult.java:125)
	at junit.framework.TestCase.run(TestCase.java:129)
	at junit.framework.TestSuite.runTest(TestSuite.java:255)
	at junit.framework.TestSuite.run(TestSuite.java:250)
	at org.junit.internal.runners.JUnit38ClassRunner.run(JUnit38ClassRunner.java:84)
	at org.eclipse.jdt.internal.junit4.runner.JUnit4TestReference.run(JUnit4TestReference.java:50)
	at org.eclipse.jdt.internal.junit.runner.TestExecution.run(TestExecution.java:38)
	at org.eclipse.jdt.internal.junit.runner.RemoteTestRunner.runTests(RemoteTestRunner.java:459)
	at org.eclipse.jdt.internal.junit.runner.RemoteTestRunner.runTests(RemoteTestRunner.java:675)
	at org.eclipse.jdt.internal.junit.runner.RemoteTestRunner.run(RemoteTestRunner.java:382)
	at org.eclipse.jdt.internal.junit.runner.RemoteTestRunner.main(RemoteTestRunner.java:192)

</failure>
    </testcase>
    <testcase name="testSingleDenseSetSize1000" classname="DoubleVectorTester" time="0.0"/>
    <testcase name="testL1NormDenseLong" classname="DoubleVectorTester" time="0.0"/>
    <testcase name="testLotsOfDenseSetsWithAddToAll" classname="DoubleVectorTester" time="0.0"/>
  </testsuite>
</testrun>
